{
 "cells": [
  {
   "cell_type": "code",
   "execution_count": 5,
   "id": "477f534b-01f4-4170-9885-5f4d2da7fcae",
   "metadata": {
    "_cell_guid": "b1076dfc-b9ad-4769-8c92-a6c4dae69d19",
    "_uuid": "8f2839f25d086af736a60e9eeb907d3b93b6e0e5"
   },
   "outputs": [],
   "source": [
    "import gc\n",
    "import geopandas as gpd\n",
    "import matplotlib as mpl\n",
    "import matplotlib.pyplot as plt\n",
    "import numpy as np\n",
    "import os\n",
    "import pandas as pd \n",
    "import pickle\n",
    "from sklearn.model_selection import GridSearchCV, ParameterGrid, train_test_split\n",
    "from tqdm import tqdm\n",
    "from xgboost import XGBClassifier"
   ]
  },
  {
   "cell_type": "code",
   "execution_count": 2,
   "id": "13837574-0e51-432b-8a2a-fb701e8a3608",
   "metadata": {},
   "outputs": [],
   "source": [
    "X = pd.read_csv(\"X_train.csv\")\n",
    "y = pd.read_csv(\"y_train.csv\")"
   ]
  },
  {
   "cell_type": "code",
   "execution_count": 10,
   "id": "f56883df-a0fb-49bf-a791-b7dd6cf1f872",
   "metadata": {
    "tags": []
   },
   "outputs": [],
   "source": [
    "# Sample 20% of the training set to be used in the cross-validation to save time\n",
    "X_2, X_train, y_2, y_train = train_test_split(X, y, test_size=0.2, random_state=1)"
   ]
  },
  {
   "cell_type": "code",
   "execution_count": 17,
   "id": "96f7be23-41ae-40f1-a357-a8c94f8ddce1",
   "metadata": {
    "tags": []
   },
   "outputs": [],
   "source": [
    "# Implement grid search from sklearn\n",
    "cv_params = {'max_depth': [[2], [4], [6]], 'colsample_bynode': [[0.6], [0.8], [1]]}\n",
    "param_grid = list(ParameterGrid(cv_params))\n",
    "fit_params = {'objective': 'binary:logistic', \n",
    "              'eval_metric': ['error','logloss'],\n",
    "              'early_stopping_rounds': 10}"
   ]
  },
  {
   "cell_type": "code",
   "execution_count": 19,
   "id": "096bbedc-622b-4da0-90e9-1a7e535fe634",
   "metadata": {
    "tags": []
   },
   "outputs": [
    {
     "name": "stdout",
     "output_type": "stream",
     "text": [
      "[{'colsample_bynode': [0.6], 'max_depth': [2]}, {'colsample_bynode': [0.6], 'max_depth': [4]}, {'colsample_bynode': [0.6], 'max_depth': [6]}, {'colsample_bynode': [0.8], 'max_depth': [2]}, {'colsample_bynode': [0.8], 'max_depth': [4]}, {'colsample_bynode': [0.8], 'max_depth': [6]}, {'colsample_bynode': [1], 'max_depth': [2]}, {'colsample_bynode': [1], 'max_depth': [4]}, {'colsample_bynode': [1], 'max_depth': [6]}]\n"
     ]
    }
   ],
   "source": [
    "print(param_grid)"
   ]
  },
  {
   "cell_type": "code",
   "execution_count": 18,
   "id": "d9671b8d-2b16-48ae-9cdd-e3a9bdf42fe4",
   "metadata": {},
   "outputs": [
    {
     "ename": "ValueError",
     "evalue": "\nAll the 27 fits failed.\nIt is very likely that your model is misconfigured.\nYou can try to debug the error by setting error_score='raise'.\n\nBelow are more details about the failures:\n--------------------------------------------------------------------------------\n27 fits failed with the following error:\nTraceback (most recent call last):\n  File \"/opt/conda/lib/python3.10/site-packages/sklearn/model_selection/_validation.py\", line 895, in _fit_and_score\n    estimator.fit(X_train, y_train, **fit_params)\n  File \"/opt/conda/lib/python3.10/site-packages/xgboost/core.py\", line 730, in inner_f\n    return func(**kwargs)\nTypeError: XGBClassifier.fit() got an unexpected keyword argument 'objective'\n",
     "output_type": "error",
     "traceback": [
      "\u001b[0;31m---------------------------------------------------------------------------\u001b[0m",
      "\u001b[0;31mValueError\u001b[0m                                Traceback (most recent call last)",
      "File \u001b[0;32m<timed exec>:2\u001b[0m\n",
      "File \u001b[0;32m/opt/conda/lib/python3.10/site-packages/sklearn/base.py:1474\u001b[0m, in \u001b[0;36m_fit_context.<locals>.decorator.<locals>.wrapper\u001b[0;34m(estimator, *args, **kwargs)\u001b[0m\n\u001b[1;32m   1467\u001b[0m     estimator\u001b[38;5;241m.\u001b[39m_validate_params()\n\u001b[1;32m   1469\u001b[0m \u001b[38;5;28;01mwith\u001b[39;00m config_context(\n\u001b[1;32m   1470\u001b[0m     skip_parameter_validation\u001b[38;5;241m=\u001b[39m(\n\u001b[1;32m   1471\u001b[0m         prefer_skip_nested_validation \u001b[38;5;129;01mor\u001b[39;00m global_skip_validation\n\u001b[1;32m   1472\u001b[0m     )\n\u001b[1;32m   1473\u001b[0m ):\n\u001b[0;32m-> 1474\u001b[0m     \u001b[38;5;28;01mreturn\u001b[39;00m \u001b[43mfit_method\u001b[49m\u001b[43m(\u001b[49m\u001b[43mestimator\u001b[49m\u001b[43m,\u001b[49m\u001b[43m \u001b[49m\u001b[38;5;241;43m*\u001b[39;49m\u001b[43margs\u001b[49m\u001b[43m,\u001b[49m\u001b[43m \u001b[49m\u001b[38;5;241;43m*\u001b[39;49m\u001b[38;5;241;43m*\u001b[39;49m\u001b[43mkwargs\u001b[49m\u001b[43m)\u001b[49m\n",
      "File \u001b[0;32m/opt/conda/lib/python3.10/site-packages/sklearn/model_selection/_search.py:970\u001b[0m, in \u001b[0;36mBaseSearchCV.fit\u001b[0;34m(self, X, y, **params)\u001b[0m\n\u001b[1;32m    964\u001b[0m     results \u001b[38;5;241m=\u001b[39m \u001b[38;5;28mself\u001b[39m\u001b[38;5;241m.\u001b[39m_format_results(\n\u001b[1;32m    965\u001b[0m         all_candidate_params, n_splits, all_out, all_more_results\n\u001b[1;32m    966\u001b[0m     )\n\u001b[1;32m    968\u001b[0m     \u001b[38;5;28;01mreturn\u001b[39;00m results\n\u001b[0;32m--> 970\u001b[0m \u001b[38;5;28;43mself\u001b[39;49m\u001b[38;5;241;43m.\u001b[39;49m\u001b[43m_run_search\u001b[49m\u001b[43m(\u001b[49m\u001b[43mevaluate_candidates\u001b[49m\u001b[43m)\u001b[49m\n\u001b[1;32m    972\u001b[0m \u001b[38;5;66;03m# multimetric is determined here because in the case of a callable\u001b[39;00m\n\u001b[1;32m    973\u001b[0m \u001b[38;5;66;03m# self.scoring the return type is only known after calling\u001b[39;00m\n\u001b[1;32m    974\u001b[0m first_test_score \u001b[38;5;241m=\u001b[39m all_out[\u001b[38;5;241m0\u001b[39m][\u001b[38;5;124m\"\u001b[39m\u001b[38;5;124mtest_scores\u001b[39m\u001b[38;5;124m\"\u001b[39m]\n",
      "File \u001b[0;32m/opt/conda/lib/python3.10/site-packages/sklearn/model_selection/_search.py:1527\u001b[0m, in \u001b[0;36mGridSearchCV._run_search\u001b[0;34m(self, evaluate_candidates)\u001b[0m\n\u001b[1;32m   1525\u001b[0m \u001b[38;5;28;01mdef\u001b[39;00m \u001b[38;5;21m_run_search\u001b[39m(\u001b[38;5;28mself\u001b[39m, evaluate_candidates):\n\u001b[1;32m   1526\u001b[0m \u001b[38;5;250m    \u001b[39m\u001b[38;5;124;03m\"\"\"Search all candidates in param_grid\"\"\"\u001b[39;00m\n\u001b[0;32m-> 1527\u001b[0m     \u001b[43mevaluate_candidates\u001b[49m\u001b[43m(\u001b[49m\u001b[43mParameterGrid\u001b[49m\u001b[43m(\u001b[49m\u001b[38;5;28;43mself\u001b[39;49m\u001b[38;5;241;43m.\u001b[39;49m\u001b[43mparam_grid\u001b[49m\u001b[43m)\u001b[49m\u001b[43m)\u001b[49m\n",
      "File \u001b[0;32m/opt/conda/lib/python3.10/site-packages/sklearn/model_selection/_search.py:947\u001b[0m, in \u001b[0;36mBaseSearchCV.fit.<locals>.evaluate_candidates\u001b[0;34m(candidate_params, cv, more_results)\u001b[0m\n\u001b[1;32m    940\u001b[0m \u001b[38;5;28;01melif\u001b[39;00m \u001b[38;5;28mlen\u001b[39m(out) \u001b[38;5;241m!=\u001b[39m n_candidates \u001b[38;5;241m*\u001b[39m n_splits:\n\u001b[1;32m    941\u001b[0m     \u001b[38;5;28;01mraise\u001b[39;00m \u001b[38;5;167;01mValueError\u001b[39;00m(\n\u001b[1;32m    942\u001b[0m         \u001b[38;5;124m\"\u001b[39m\u001b[38;5;124mcv.split and cv.get_n_splits returned \u001b[39m\u001b[38;5;124m\"\u001b[39m\n\u001b[1;32m    943\u001b[0m         \u001b[38;5;124m\"\u001b[39m\u001b[38;5;124minconsistent results. Expected \u001b[39m\u001b[38;5;132;01m{}\u001b[39;00m\u001b[38;5;124m \u001b[39m\u001b[38;5;124m\"\u001b[39m\n\u001b[1;32m    944\u001b[0m         \u001b[38;5;124m\"\u001b[39m\u001b[38;5;124msplits, got \u001b[39m\u001b[38;5;132;01m{}\u001b[39;00m\u001b[38;5;124m\"\u001b[39m\u001b[38;5;241m.\u001b[39mformat(n_splits, \u001b[38;5;28mlen\u001b[39m(out) \u001b[38;5;241m/\u001b[39m\u001b[38;5;241m/\u001b[39m n_candidates)\n\u001b[1;32m    945\u001b[0m     )\n\u001b[0;32m--> 947\u001b[0m \u001b[43m_warn_or_raise_about_fit_failures\u001b[49m\u001b[43m(\u001b[49m\u001b[43mout\u001b[49m\u001b[43m,\u001b[49m\u001b[43m \u001b[49m\u001b[38;5;28;43mself\u001b[39;49m\u001b[38;5;241;43m.\u001b[39;49m\u001b[43merror_score\u001b[49m\u001b[43m)\u001b[49m\n\u001b[1;32m    949\u001b[0m \u001b[38;5;66;03m# For callable self.scoring, the return type is only know after\u001b[39;00m\n\u001b[1;32m    950\u001b[0m \u001b[38;5;66;03m# calling. If the return type is a dictionary, the error scores\u001b[39;00m\n\u001b[1;32m    951\u001b[0m \u001b[38;5;66;03m# can now be inserted with the correct key. The type checking\u001b[39;00m\n\u001b[1;32m    952\u001b[0m \u001b[38;5;66;03m# of out will be done in `_insert_error_scores`.\u001b[39;00m\n\u001b[1;32m    953\u001b[0m \u001b[38;5;28;01mif\u001b[39;00m \u001b[38;5;28mcallable\u001b[39m(\u001b[38;5;28mself\u001b[39m\u001b[38;5;241m.\u001b[39mscoring):\n",
      "File \u001b[0;32m/opt/conda/lib/python3.10/site-packages/sklearn/model_selection/_validation.py:536\u001b[0m, in \u001b[0;36m_warn_or_raise_about_fit_failures\u001b[0;34m(results, error_score)\u001b[0m\n\u001b[1;32m    529\u001b[0m \u001b[38;5;28;01mif\u001b[39;00m num_failed_fits \u001b[38;5;241m==\u001b[39m num_fits:\n\u001b[1;32m    530\u001b[0m     all_fits_failed_message \u001b[38;5;241m=\u001b[39m (\n\u001b[1;32m    531\u001b[0m         \u001b[38;5;124mf\u001b[39m\u001b[38;5;124m\"\u001b[39m\u001b[38;5;130;01m\\n\u001b[39;00m\u001b[38;5;124mAll the \u001b[39m\u001b[38;5;132;01m{\u001b[39;00mnum_fits\u001b[38;5;132;01m}\u001b[39;00m\u001b[38;5;124m fits failed.\u001b[39m\u001b[38;5;130;01m\\n\u001b[39;00m\u001b[38;5;124m\"\u001b[39m\n\u001b[1;32m    532\u001b[0m         \u001b[38;5;124m\"\u001b[39m\u001b[38;5;124mIt is very likely that your model is misconfigured.\u001b[39m\u001b[38;5;130;01m\\n\u001b[39;00m\u001b[38;5;124m\"\u001b[39m\n\u001b[1;32m    533\u001b[0m         \u001b[38;5;124m\"\u001b[39m\u001b[38;5;124mYou can try to debug the error by setting error_score=\u001b[39m\u001b[38;5;124m'\u001b[39m\u001b[38;5;124mraise\u001b[39m\u001b[38;5;124m'\u001b[39m\u001b[38;5;124m.\u001b[39m\u001b[38;5;130;01m\\n\u001b[39;00m\u001b[38;5;130;01m\\n\u001b[39;00m\u001b[38;5;124m\"\u001b[39m\n\u001b[1;32m    534\u001b[0m         \u001b[38;5;124mf\u001b[39m\u001b[38;5;124m\"\u001b[39m\u001b[38;5;124mBelow are more details about the failures:\u001b[39m\u001b[38;5;130;01m\\n\u001b[39;00m\u001b[38;5;132;01m{\u001b[39;00mfit_errors_summary\u001b[38;5;132;01m}\u001b[39;00m\u001b[38;5;124m\"\u001b[39m\n\u001b[1;32m    535\u001b[0m     )\n\u001b[0;32m--> 536\u001b[0m     \u001b[38;5;28;01mraise\u001b[39;00m \u001b[38;5;167;01mValueError\u001b[39;00m(all_fits_failed_message)\n\u001b[1;32m    538\u001b[0m \u001b[38;5;28;01melse\u001b[39;00m:\n\u001b[1;32m    539\u001b[0m     some_fits_failed_message \u001b[38;5;241m=\u001b[39m (\n\u001b[1;32m    540\u001b[0m         \u001b[38;5;124mf\u001b[39m\u001b[38;5;124m\"\u001b[39m\u001b[38;5;130;01m\\n\u001b[39;00m\u001b[38;5;132;01m{\u001b[39;00mnum_failed_fits\u001b[38;5;132;01m}\u001b[39;00m\u001b[38;5;124m fits failed out of a total of \u001b[39m\u001b[38;5;132;01m{\u001b[39;00mnum_fits\u001b[38;5;132;01m}\u001b[39;00m\u001b[38;5;124m.\u001b[39m\u001b[38;5;130;01m\\n\u001b[39;00m\u001b[38;5;124m\"\u001b[39m\n\u001b[1;32m    541\u001b[0m         \u001b[38;5;124m\"\u001b[39m\u001b[38;5;124mThe score on these train-test partitions for these parameters\u001b[39m\u001b[38;5;124m\"\u001b[39m\n\u001b[0;32m   (...)\u001b[0m\n\u001b[1;32m    545\u001b[0m         \u001b[38;5;124mf\u001b[39m\u001b[38;5;124m\"\u001b[39m\u001b[38;5;124mBelow are more details about the failures:\u001b[39m\u001b[38;5;130;01m\\n\u001b[39;00m\u001b[38;5;132;01m{\u001b[39;00mfit_errors_summary\u001b[38;5;132;01m}\u001b[39;00m\u001b[38;5;124m\"\u001b[39m\n\u001b[1;32m    546\u001b[0m     )\n",
      "\u001b[0;31mValueError\u001b[0m: \nAll the 27 fits failed.\nIt is very likely that your model is misconfigured.\nYou can try to debug the error by setting error_score='raise'.\n\nBelow are more details about the failures:\n--------------------------------------------------------------------------------\n27 fits failed with the following error:\nTraceback (most recent call last):\n  File \"/opt/conda/lib/python3.10/site-packages/sklearn/model_selection/_validation.py\", line 895, in _fit_and_score\n    estimator.fit(X_train, y_train, **fit_params)\n  File \"/opt/conda/lib/python3.10/site-packages/xgboost/core.py\", line 730, in inner_f\n    return func(**kwargs)\nTypeError: XGBClassifier.fit() got an unexpected keyword argument 'objective'\n"
     ]
    }
   ],
   "source": [
    "%%time\n",
    "gridsearch = GridSearchCV(XGBClassifier(), param_grid, cv=3)\n",
    "gridsearch.fit(X_train, y_train, **fit_params)"
   ]
  },
  {
   "cell_type": "code",
   "execution_count": null,
   "id": "961a543c-105c-413c-9b93-d425340a4842",
   "metadata": {},
   "outputs": [],
   "source": []
  }
 ],
 "metadata": {
  "environment": {
   "kernel": "python3",
   "name": "tf2-cpu.2-11.m121",
   "type": "gcloud",
   "uri": "us-docker.pkg.dev/deeplearning-platform-release/gcr.io/tf2-cpu.2-11:m121"
  },
  "kernelspec": {
   "display_name": "Python 3 (Local)",
   "language": "python",
   "name": "python3"
  },
  "language_info": {
   "codemirror_mode": {
    "name": "ipython",
    "version": 3
   },
   "file_extension": ".py",
   "mimetype": "text/x-python",
   "name": "python",
   "nbconvert_exporter": "python",
   "pygments_lexer": "ipython3",
   "version": "3.10.14"
  }
 },
 "nbformat": 4,
 "nbformat_minor": 5
}
